[2024-06-16 12:42:27 +0800] [1409220] [INFO] Starting gunicorn 22.0.0
[2024-06-16 12:42:27 +0800] [1409220] [INFO] Listening at: http://0.0.0.0:5001 (1409220)
[2024-06-16 12:42:27 +0800] [1409220] [INFO] Using worker: sync
[2024-06-16 12:42:27 +0800] [1409223] [INFO] Booting worker with pid: 1409223
[2024-06-16 12:42:27 +0800] [1409224] [INFO] Booting worker with pid: 1409224
[2024-06-16 12:42:32 +0800] [1409223] [ERROR] Exception in worker process
Traceback (most recent call last):
  File "/root/anaconda3/envs/sai/lib/python3.8/site-packages/gunicorn/arbiter.py", line 609, in spawn_worker
    worker.init_process()
  File "/root/anaconda3/envs/sai/lib/python3.8/site-packages/gunicorn/workers/base.py", line 134, in init_process
    self.load_wsgi()
  File "/root/anaconda3/envs/sai/lib/python3.8/site-packages/gunicorn/workers/base.py", line 146, in load_wsgi
    self.wsgi = self.app.wsgi()
  File "/root/anaconda3/envs/sai/lib/python3.8/site-packages/gunicorn/app/base.py", line 67, in wsgi
    self.callable = self.load()
  File "/root/anaconda3/envs/sai/lib/python3.8/site-packages/gunicorn/app/wsgiapp.py", line 58, in load
    return self.load_wsgiapp()
  File "/root/anaconda3/envs/sai/lib/python3.8/site-packages/gunicorn/app/wsgiapp.py", line 48, in load_wsgiapp
    return util.import_app(self.app_uri)
  File "/root/anaconda3/envs/sai/lib/python3.8/site-packages/gunicorn/util.py", line 371, in import_app
    mod = importlib.import_module(module)
  File "/root/anaconda3/envs/sai/lib/python3.8/importlib/__init__.py", line 127, in import_module
    return _bootstrap._gcd_import(name[level:], package, level)
  File "<frozen importlib._bootstrap>", line 1014, in _gcd_import
  File "<frozen importlib._bootstrap>", line 991, in _find_and_load
  File "<frozen importlib._bootstrap>", line 975, in _find_and_load_unlocked
  File "<frozen importlib._bootstrap>", line 671, in _load_unlocked
  File "<frozen importlib._bootstrap_external>", line 843, in exec_module
  File "<frozen importlib._bootstrap>", line 219, in _call_with_frames_removed
  File "/home/SAI/tts.py", line 16, in <module>
    output_config = config.Config("./output_data.json")
  File "/home/SAI/config.py", line 18, in __init__
    self.__content: dict = json.loads(self.file.read())
  File "/root/anaconda3/envs/sai/lib/python3.8/json/__init__.py", line 357, in loads
    return _default_decoder.decode(s)
  File "/root/anaconda3/envs/sai/lib/python3.8/json/decoder.py", line 340, in decode
    raise JSONDecodeError("Extra data", s, end)
json.decoder.JSONDecodeError: Extra data: line 3 column 8 (char 29)
[2024-06-16 12:42:32 +0800] [1409223] [INFO] Worker exiting (pid: 1409223)
[2024-06-16 12:42:32 +0800] [1409224] [ERROR] Exception in worker process
Traceback (most recent call last):
  File "/root/anaconda3/envs/sai/lib/python3.8/site-packages/gunicorn/arbiter.py", line 609, in spawn_worker
    worker.init_process()
  File "/root/anaconda3/envs/sai/lib/python3.8/site-packages/gunicorn/workers/base.py", line 134, in init_process
    self.load_wsgi()
  File "/root/anaconda3/envs/sai/lib/python3.8/site-packages/gunicorn/workers/base.py", line 146, in load_wsgi
    self.wsgi = self.app.wsgi()
  File "/root/anaconda3/envs/sai/lib/python3.8/site-packages/gunicorn/app/base.py", line 67, in wsgi
    self.callable = self.load()
  File "/root/anaconda3/envs/sai/lib/python3.8/site-packages/gunicorn/app/wsgiapp.py", line 58, in load
    return self.load_wsgiapp()
  File "/root/anaconda3/envs/sai/lib/python3.8/site-packages/gunicorn/app/wsgiapp.py", line 48, in load_wsgiapp
    return util.import_app(self.app_uri)
  File "/root/anaconda3/envs/sai/lib/python3.8/site-packages/gunicorn/util.py", line 371, in import_app
    mod = importlib.import_module(module)
  File "/root/anaconda3/envs/sai/lib/python3.8/importlib/__init__.py", line 127, in import_module
    return _bootstrap._gcd_import(name[level:], package, level)
  File "<frozen importlib._bootstrap>", line 1014, in _gcd_import
  File "<frozen importlib._bootstrap>", line 991, in _find_and_load
  File "<frozen importlib._bootstrap>", line 975, in _find_and_load_unlocked
  File "<frozen importlib._bootstrap>", line 671, in _load_unlocked
  File "<frozen importlib._bootstrap_external>", line 843, in exec_module
  File "<frozen importlib._bootstrap>", line 219, in _call_with_frames_removed
  File "/home/SAI/tts.py", line 16, in <module>
    output_config = config.Config("./output_data.json")
  File "/home/SAI/config.py", line 18, in __init__
    self.__content: dict = json.loads(self.file.read())
  File "/root/anaconda3/envs/sai/lib/python3.8/json/__init__.py", line 357, in loads
    return _default_decoder.decode(s)
  File "/root/anaconda3/envs/sai/lib/python3.8/json/decoder.py", line 340, in decode
    raise JSONDecodeError("Extra data", s, end)
json.decoder.JSONDecodeError: Extra data: line 3 column 8 (char 29)
[2024-06-16 12:42:32 +0800] [1409224] [INFO] Worker exiting (pid: 1409224)
[2024-06-16 12:42:33 +0800] [1409220] [ERROR] Worker (pid:1409223) exited with code 3
[2024-06-16 12:43:04 +0800] [1409220] [ERROR] Shutting down: Master
[2024-06-16 12:43:04 +0800] [1409220] [ERROR] Reason: Worker failed to boot.
